Workbook

Sheet Dashboard Gerencial
A1: GRUPO TERRACOP - DASHBOARD DE CONTROL GERENCIAL
A2: Resumen ejecutivo en tiempo real de Licitaciones Comerciales y Disponibilidad Operativa de Flota
A4: ESTADO DE LA FLOTA Y TALLER | D4: ESTADO DE LICITACIONES Y SOLICITUDES | G4: INDICADORES CLAVE (KPIs)
A5: Estado Operacional | B5: Cantidad Equipos | D5: Estado Comercial | E5: Cantidad | G5: KPI Estratégico | H5: Resultado
A6: Disponibles Inmediatos (Viñita) | B6: =COUNTIF('2. Control Flota y Taller'!M5:M112, "🟢*") -> 36 | D6: En Revisión / Preparación | E6: =COUNTIF('1. Solicitudes y Cotizaciones'!J5:J60, "*Revisión*") -> 0 | G6: Disponibilidad Operacional Flota (%) | H6: =(B6+B7)/B10 -> 0.85185185
A7: En Operación con Mandante | B7: =COUNTIF('2. Control Flota y Taller'!M5:M112, "🔵*") -> 33 | D7: Cotizaciones Enviadas | E7: =COUNTIF('1. Solicitudes y Cotizaciones'!J5:J60, "*Enviada*") -> 1 | G7: Tasa de Adjudicación Comercial (%) | H7: =E8/E10 -> 0.5
A8: En Mantención / Taller | B8: =COUNTIF('2. Control Flota y Taller'!M5:M112, "🟡*") -> 2 | D8: Adjudicadas / Ganadas | E8: =COUNTIF('1. Solicitudes y Cotizaciones'!K5:K60, "*Ganada*") -> 1 | G8: Alertas de Cotización Vencidas / Críticas | H8: =COUNTIF('1. Solicitudes y Cotizaciones'!K5:K50, "🔴*") -> 0
A9: No Operativos / Atraso Taller | B9: =COUNTIF('2. Control Flota y Taller'!M5:M112, "🔴*") -> 10 | D9: No Adjudicadas / Declinadas | E9: =COUNTIF('1. Solicitudes y Cotizaciones'!K5:K60, "*No Adjudicada*") + COUNTIF('1. Solicitudes y Cotizaciones'!K5:K60, "*Declinada*") -> 0 | G9: Equipos con Demora Crítica en Taller | H9: =COUNTIF('2. Control Flota y Taller'!M5:M112, "🔴 DEMORA*") -> 0
A10: TOTAL FLOTA REGISTRADA | B10: =SUM(B6:B9) -> 81 | D10: TOTAL SOLICITUDES | E10: =SUM(E6:E9) -> 2

Sheet 1. Solicitudes y Cotizaciones
A1: GRUPO TERRACOP - CONTROL DE SOLICITUDES, COTIZACIONES Y LICITACIONES
A2: Pincha el menú desplegable en cada celda para cambiar el estado. El tiempo de respuesta y la alerta se calculan automáticamente.
A4: ID | B4: Fecha Solicitud | C4: Mandante / Cliente | D4: Línea de Negocio | E4: Requerimiento / Equipo | F4: Plazo (Días) | G4: Fecha Límite Cotizar | H4: Fecha Envío Cotización | I4: Días Demora / Transcurridos | J4: ESTADO COTIZACIÓN (CHECK) | K4: RESULTADO / ADJUDICACIÓN (CHECK) | L4: ALERTA AUTOMÁTICA SLA | M4: Monto Cotizado (CLP) | N4: Observaciones / Seguimiento | O4: fecha envio equipo | P4: individualización equipo
A5: CTZ 1221 | B5: 46262 | C5: FG COVER (Fenix Gold) | D5: Movimiento de Tierra | E5: 1x Excavadora CAT 320 por 30 días turno día | F5: 30 | G5: 46264 | H5: 46262 | I5: =IF(B5="","",IF(H5<>"", H5-B5, TODAY()-B5)) -> 0 | J5: 🔵 Cotización Enviada | K5: 🟢 Adjudicada / Ganada | L5: =IF(B5="","", IF(ISNUMBER(SEARCH("Adjudicada / Ganada", K5)), "✅ Adjudicada", IF(ISNUMBER(SEARCH("No Adjudicada", K5)), "🔴 No Adjudicada", IF(OR(ISNUMBER(SEARCH("Declinada", K5)), ISNUMBER(SEARCH("No Enviada", J5))), "⚪ Declinada / No Cotizada", IF(ISNUMBER(SEARCH("Enviada", J5)), "📬 Cotización Enviada", IF(TODAY()>G5, "🔴 Atrasada / Vencida", IF(G5-TODAY()<=2, "🟡 Por Vencer (≤48h)", "🟢 En Plazo"))))))) -> ✅ Adjudicada | M5: 20633360 | N5: gestionando operatividad equipo, operador en faena | O5: 46266 | P5: HYPS-60 (EX-209)
I10: =IF(B10="","",IF(H10<>"", H10-B10, TODAY()-B10)) | K10: =IF(B10="","", IF(ISNUMBER(SEARCH("Declinada",J10)), "⚪ Declinada / No Adjudicada", IF(ISNUMBER(SEARCH("Ganada",J10)), "✅ Adjudicada", IF(ISNUMBER(SEARCH("Enviada",J10)), "📬 Cotización Enviada", IF(TODAY()>G10, "🔴 Atrasada / Vencida", IF(G10-TODAY()<=2, "🟡 Por Vencer (≤48h)", "🟢 En Plazo")))))) | L10: =IF(B10="","", IF(ISNUMBER(SEARCH("Adjudicada / Ganada", K10)), "✅ Adjudicada", IF(ISNUMBER(SEARCH("No Adjudicada", K10)), "🔴 No Adjudicada", IF(OR(ISNUMBER(SEARCH("Declinada", K10)), ISNUMBER(SEARCH("No Enviada", J10))), "⚪ Declinada / No Cotizada", IF(ISNUMBER(SEARCH("Enviada", J10)), "📬 Cotización Enviada", IF(TODAY()>G10, "🔴 Atrasada / Vencida", IF(G10-TODAY()<=2, "🟡 Por Vencer (≤48h)", "🟢 En Plazo")))))))
I11: =IF(B11="","",IF(H11<>"", H11-B11, TODAY()-B11)) | K11: =IF(B11="","", IF(ISNUMBER(SEARCH("Declinada",J11)), "⚪ Declinada / No Adjudicada", IF(ISNUMBER(SEARCH("Ganada",J11)), "✅ Adjudicada", IF(ISNUMBER(SEARCH("Enviada",J11)), "📬 Cotización Enviada", IF(TODAY()>G11, "🔴 Atrasada / Vencida", IF(G11-TODAY()<=2, "🟡 Por Vencer (≤48h)", "🟢 En Plazo")))))) | L11: =IF(B11="","", IF(ISNUMBER(SEARCH("Adjudicada / Ganada", K11)), "✅ Adjudicada", IF(ISNUMBER(SEARCH("No Adjudicada", K11)), "🔴 No Adjudicada", IF(OR(ISNUMBER(SEARCH("Declinada", K11)), ISNUMBER(SEARCH("No Enviada", J11))), "⚪ Declinada / No Cotizada", IF(ISNUMBER(SEARCH("Enviada", J11)), "📬 Cotización Enviada", IF(TODAY()>G11, "🔴 Atrasada / Vencida", IF(G11-TODAY()<=2, "🟡 Por Vencer (≤48h)", "🟢 En Plazo")))))))
I12: =IF(B12="","",IF(H12<>"", H12-B12, TODAY()-B12)) | K12: =IF(B12="","", IF(ISNUMBER(SEARCH("Declinada",J12)), "⚪ Declinada / No Adjudicada", IF(ISNUMBER(SEARCH("Ganada",J12)), "✅ Adjudicada", IF(ISNUMBER(SEARCH("Enviada",J12)), "📬 Cotización Enviada", IF(TODAY()>G12, "🔴 Atrasada / Vencida", IF(G12-TODAY()<=2, "🟡 Por Vencer (≤48h)", "🟢 En Plazo")))))) | L12: =IF(B12="","", IF(ISNUMBER(SEARCH("Adjudicada / Ganada", K12)), "✅ Adjudicada", IF(ISNUMBER(SEARCH("No Adjudicada", K12)), "🔴 No Adjudicada", IF(OR(ISNUMBER(SEARCH("Declinada", K12)), ISNUMBER(SEARCH("No Enviada", J12))), "⚪ Declinada / No Cotizada", IF(ISNUMBER(SEARCH("Enviada", J12)), "📬 Cotización Enviada", IF(TODAY()>G12, "🔴 Atrasada / Vencida", IF(G12-TODAY()<=2, "🟡 Por Vencer (≤48h)", "🟢 En Plazo")))))))
I13: =IF(B13="","",IF(H13<>"", H13-B13, TODAY()-B13)) | K13: =IF(B13="","", IF(ISNUMBER(SEARCH("Declinada",J13)), "⚪ Declinada / No Adjudicada", IF(ISNUMBER(SEARCH("Ganada",J13)), "✅ Adjudicada", IF(ISNUMBER(SEARCH("Enviada",J13)), "📬 Cotización Enviada", IF(TODAY()>G13, "🔴 Atrasada / Vencida", IF(G13-TODAY()<=2, "🟡 Por Vencer (≤48h)", "🟢 En Plazo")))))) | L13: =IF(B13="","", IF(ISNUMBER(SEARCH("Adjudicada / Ganada", K13)), "✅ Adjudicada", IF(ISNUMBER(SEARCH("No Adjudicada", K13)), "🔴 No Adjudicada", IF(OR(ISNUMBER(SEARCH("Declinada", K13)), ISNUMBER(SEARCH("No Enviada", J13))), "⚪ Declinada / No Cotizada", IF(ISNUMBER(SEARCH("Enviada", J13)), "📬 Cotización Enviada", IF(TODAY()>G13, "🔴 Atrasada / Vencida", IF(G13-TODAY()<=2, "🟡 Por Vencer (≤48h)", "🟢 En Plazo")))))))
I14: =IF(B14="","",IF(H14<>"", H14-B14, TODAY()-B14)) | K14: =IF(B14="","", IF(ISNUMBER(SEARCH("Declinada",J14)), "⚪ Declinada / No Adjudicada", IF(ISNUMBER(SEARCH("Ganada",J14)), "✅ Adjudicada", IF(ISNUMBER(SEARCH("Enviada",J14)), "📬 Cotización Enviada", IF(TODAY()>G14, "🔴 Atrasada / Vencida", IF(G14-TODAY()<=2, "🟡 Por Vencer (≤48h)", "🟢 En Plazo")))))) | L14: =IF(B14="","", IF(ISNUMBER(SEARCH("Adjudicada / Ganada", K14)), "✅ Adjudicada", IF(ISNUMBER(SEARCH("No Adjudicada", K14)), "🔴 No Adjudicada", IF(OR(ISNUMBER(SEARCH("Declinada", K14)), ISNUMBER(SEARCH("No Enviada", J14))), "⚪ Declinada / No Cotizada", IF(ISNUMBER(SEARCH("Enviada", J14)), "📬 Cotización Enviada", IF(TODAY()>G14, "🔴 Atrasada / Vencida", IF(G14-TODAY()<=2, "🟡 Por Vencer (≤48h)", "🟢 En Plazo")))))))
I15: =IF(B15="","",IF(H15<>"", H15-B15, TODAY()-B15)) | K15: =IF(B15="","", IF(ISNUMBER(SEARCH("Declinada",J15)), "⚪ Declinada / No Adjudicada", IF(ISNUMBER(SEARCH("Ganada",J15)), "✅ Adjudicada", IF(ISNUMBER(SEARCH("Enviada",J15)), "📬 Cotización Enviada", IF(TODAY()>G15, "🔴 Atrasada / Vencida", IF(G15-TODAY()<=2, "🟡 Por Vencer (≤48h)", "🟢 En Plazo")))))) | L15: =IF(B15="","", IF(ISNUMBER(SEARCH("Adjudicada / Ganada", K15)), "✅ Adjudicada", IF(ISNUMBER(SEARCH("No Adjudicada", K15)), "🔴 No Adjudicada", IF(OR(ISNUMBER(SEARCH("Declinada", K15)), ISNUMBER(SEARCH("No Enviada", J15))), "⚪ Declinada / No Cotizada", IF(ISNUMBER(SEARCH("Enviada", J15)), "📬 Cotización Enviada", IF(TODAY()>G15, "🔴 Atrasada / Vencida", IF(G15-TODAY()<=2, "🟡 Por Vencer (≤48h)", "🟢 En Plazo")))))))
I16: =IF(B16="","",IF(H16<>"", H16-B16, TODAY()-B16)) | K16: =IF(B16="","", IF(ISNUMBER(SEARCH("Declinada",J16)), "⚪ Declinada / No Adjudicada", IF(ISNUMBER(SEARCH("Ganada",J16)), "✅ Adjudicada", IF(ISNUMBER(SEARCH("Enviada",J16)), "📬 Cotización Enviada", IF(TODAY()>G16, "🔴 Atrasada / Vencida", IF(G16-TODAY()<=2, "🟡 Por Vencer (≤48h)", "🟢 En Plazo")))))) | L16: =IF(B16="","", IF(ISNUMBER(SEARCH("Adjudicada / Ganada", K16)), "✅ Adjudicada", IF(ISNUMBER(SEARCH("No Adjudicada", K16)), "🔴 No Adjudicada", IF(OR(ISNUMBER(SEARCH("Declinada", K16)), ISNUMBER(SEARCH("No Enviada", J16))), "⚪ Declinada / No Cotizada", IF(ISNUMBER(SEARCH("Enviada", J16)), "📬 Cotización Enviada", IF(TODAY()>G16, "🔴 Atrasada / Vencida", IF(G16-TODAY()<=2, "🟡 Por Vencer (≤48h)", "🟢 En Plazo")))))))
I17: =IF(B17="","",IF(H17<>"", H17-B17, TODAY()-B17)) | K17: =IF(B17="","", IF(ISNUMBER(SEARCH("Declinada",J17)), "⚪ Declinada / No Adjudicada", IF(ISNUMBER(SEARCH("Ganada",J17)), "✅ Adjudicada", IF(ISNUMBER(SEARCH("Enviada",J17)), "📬 Cotización Enviada", IF(TODAY()>G17, "🔴 Atrasada / Vencida", IF(G17-TODAY()<=2, "🟡 Por Vencer (≤48h)", "🟢 En Plazo")))))) | L17: =IF(B17="","", IF(ISNUMBER(SEARCH("Adjudicada / Ganada", K17)), "✅ Adjudicada", IF(ISNUMBER(SEARCH("No Adjudicada", K17)), "🔴 No Adjudicada", IF(OR(ISNUMBER(SEARCH("Declinada", K17)), ISNUMBER(SEARCH("No Enviada", J17))), "⚪ Declinada / No Cotizada", IF(ISNUMBER(SEARCH("Enviada", J17)), "📬 Cotización Enviada", IF(TODAY()>G17, "🔴 Atrasada / Vencida", IF(G17-TODAY()<=2, "🟡 Por Vencer (≤48h)", "🟢 En Plazo")))))))
I18: =IF(B18="","",IF(H18<>"", H18-B18, TODAY()-B18)) | K18: =IF(B18="","", IF(ISNUMBER(SEARCH("Declinada",J18)), "⚪ Declinada / No Adjudicada", IF(ISNUMBER(SEARCH("Ganada",J18)), "✅ Adjudicada", IF(ISNUMBER(SEARCH("Enviada",J18)), "📬 Cotización Enviada", IF(TODAY()>G18, "🔴 Atrasada / Vencida", IF(G18-TODAY()<=2, "🟡 Por Vencer (≤48h)", "🟢 En Plazo")))))) | L18: =IF(B18="","", IF(ISNUMBER(SEARCH("Adjudicada / Ganada", K18)), "✅ Adjudicada", IF(ISNUMBER(SEARCH("No Adjudicada", K18)), "🔴 No Adjudicada", IF(OR(ISNUMBER(SEARCH("Declinada", K18)), ISNUMBER(SEARCH("No Enviada", J18))), "⚪ Declinada / No Cotizada", IF(ISNUMBER(SEARCH("Enviada", J18)), "📬 Cotización Enviada", IF(TODAY()>G18, "🔴 Atrasada / Vencida", IF(G18-TODAY()<=2, "🟡 Por Vencer (≤48h)", "🟢 En Plazo")))))))
I19: =IF(B19="","",IF(H19<>"", H19-B19, TODAY()-B19)) | K19: =IF(B19="","", IF(ISNUMBER(SEARCH("Declinada",J19)), "⚪ Declinada / No Adjudicada", IF(ISNUMBER(SEARCH("Ganada",J19)), "✅ Adjudicada", IF(ISNUMBER(SEARCH("Enviada",J19)), "📬 Cotización Enviada", IF(TODAY()>G19, "🔴 Atrasada / Vencida", IF(G19-TODAY()<=2, "🟡 Por Vencer (≤48h)", "🟢 En Plazo")))))) | L19: =IF(B19="","", IF(ISNUMBER(SEARCH("Adjudicada / Ganada", K19)), "✅ Adjudicada", IF(ISNUMBER(SEARCH("No Adjudicada", K19)), "🔴 No Adjudicada", IF(OR(ISNUMBER(SEARCH("Declinada", K19)), ISNUMBER(SEARCH("No Enviada", J19))), "⚪ Declinada / No Cotizada", IF(ISNUMBER(SEARCH("Enviada", J19)), "📬 Cotización Enviada", IF(TODAY()>G19, "🔴 Atrasada / Vencida", IF(G19-TODAY()<=2, "🟡 Por Vencer (≤48h)", "🟢 En Plazo")))))))
I20: =IF(B20="","",IF(H20<>"", H20-B20, TODAY()-B20)) | K20: =IF(B20="","", IF(ISNUMBER(SEARCH("Declinada",J20)), "⚪ Declinada / No Adjudicada", IF(ISNUMBER(SEARCH("Ganada",J20)), "✅ Adjudicada", IF(ISNUMBER(SEARCH("Enviada",J20)), "📬 Cotización Enviada", IF(TODAY()>G20, "🔴 Atrasada / Vencida", IF(G20-TODAY()<=2, "🟡 Por Vencer (≤48h)", "🟢 En Plazo")))))) | L20: =IF(B20="","", IF(ISNUMBER(SEARCH("Adjudicada / Ganada", K20)), "✅ Adjudicada", IF(ISNUMBER(SEARCH("No Adjudicada", K20)), "🔴 No Adjudicada", IF(OR(ISNUMBER(SEARCH("Declinada", K20)), ISNUMBER(SEARCH("No Enviada", J20))), "⚪ Declinada / No Cotizada", IF(ISNUMBER(SEARCH("Enviada", J20)), "📬 Cotización Enviada", IF(TODAY()>G20, "🔴 Atrasada / Vencida", IF(G20-TODAY()<=2, "🟡 Por Vencer (≤48h)", "🟢 En Plazo")))))))
I21: =IF(B21="","",IF(H21<>"", H21-B21, TODAY()-B21)) | K21: =IF(B21="","", IF(ISNUMBER(SEARCH("Declinada",J21)), "⚪ Declinada / No Adjudicada", IF(ISNUMBER(SEARCH("Ganada",J21)), "✅ Adjudicada", IF(ISNUMBER(SEARCH("Enviada",J21)), "📬 Cotización Enviada", IF(TODAY()>G21, "🔴 Atrasada / Vencida", IF(G21-TODAY()<=2, "🟡 Por Vencer (≤48h)", "🟢 En Plazo")))))) | L21: =IF(B21="","", IF(ISNUMBER(SEARCH("Adjudicada / Ganada", K21)), "✅ Adjudicada", IF(ISNUMBER(SEARCH("No Adjudicada", K21)), "🔴 No Adjudicada", IF(OR(ISNUMBER(SEARCH("Declinada", K21)), ISNUMBER(SEARCH("No Enviada", J21))), "⚪ Declinada / No Cotizada", IF(ISNUMBER(SEARCH("Enviada", J21)), "📬 Cotización Enviada", IF(TODAY()>G21, "🔴 Atrasada / Vencida", IF(G21-TODAY()<=2, "🟡 Por Vencer (≤48h)", "🟢 En Plazo")))))))
... I50: =IF(B50="","",IF(H50<>"", H50-B50, TODAY()-B50)) | K50: =IF(B50="","", IF(ISNUMBER(SEARCH("Declinada",J50)), "⚪ Declinada / No Adjudicada", IF(ISNUMBER(SEARCH("Ganada",J50)), "✅ Adjudicada", IF(ISNUMBER(SEARCH("Enviada",J50)), "📬 Cotización Enviada", IF(TODAY()>G50, "🔴 Atrasada / Vencida", IF(G50-TODAY()<=2, "🟡 Por Vencer (≤48h)", "🟢 En Plazo")))))) | L50: =IF(B50="","", IF(ISNUMBER(SEARCH("Adjudicada / Ganada", K50)), "✅ Adjudicada", IF(ISNUMBER(SEARCH("No Adjudicada", K50)), "🔴 No Adjudicada", IF(OR(ISNUMBER(SEARCH("Declinada", K50)), ISNUMBER(SEARCH("No Enviada", J50))), "⚪ Declinada / No Cotizada", IF(ISNUMBER(SEARCH("Enviada", J50)), "📬 Cotización Enviada", IF(TODAY()>G50, "🔴 Atrasada / Vencida", IF(G50-TODAY()<=2, "🟡 Por Vencer (≤48h)", "🟢 En Plazo")))))))
I51: =IF(B51="","",IF(H51<>"", H51-B51, TODAY()-B51)) | L51: =IF(B51="","", IF(ISNUMBER(SEARCH("Adjudicada / Ganada", K51)), "✅ Adjudicada", IF(ISNUMBER(SEARCH("No Adjudicada", K51)), "🔴 No Adjudicada", IF(OR(ISNUMBER(SEARCH("Declinada", K51)), ISNUMBER(SEARCH("No Enviada", J51))), "⚪ Declinada / No Cotizada", IF(ISNUMBER(SEARCH("Enviada", J51)), "📬 Cotización Enviada", IF(TODAY()>G51, "🔴 Atrasada / Vencida", IF(G51-TODAY()<=2, "🟡 Por Vencer (≤48h)", "🟢 En Plazo")))))))
I52: =IF(B52="","",IF(H52<>"", H52-B52, TODAY()-B52)) | L52: =IF(B52="","", IF(ISNUMBER(SEARCH("Adjudicada / Ganada", K52)), "✅ Adjudicada", IF(ISNUMBER(SEARCH("No Adjudicada", K52)), "🔴 No Adjudicada", IF(OR(ISNUMBER(SEARCH("Declinada", K52)), ISNUMBER(SEARCH("No Enviada", J52))), "⚪ Declinada / No Cotizada", IF(ISNUMBER(SEARCH("Enviada", J52)), "📬 Cotización Enviada", IF(TODAY()>G52, "🔴 Atrasada / Vencida", IF(G52-TODAY()<=2, "🟡 Por Vencer (≤48h)", "🟢 En Plazo")))))))
I53: =IF(B53="","",IF(H53<>"", H53-B53, TODAY()-B53)) | L53: =IF(B53="","", IF(ISNUMBER(SEARCH("Adjudicada / Ganada", K53)), "✅ Adjudicada", IF(ISNUMBER(SEARCH("No Adjudicada", K53)), "🔴 No Adjudicada", IF(OR(ISNUMBER(SEARCH("Declinada", K53)), ISNUMBER(SEARCH("No Enviada", J53))), "⚪ Declinada / No Cotizada", IF(ISNUMBER(SEARCH("Enviada", J53)), "📬 Cotización Enviada", IF(TODAY()>G53, "🔴 Atrasada / Vencida", IF(G53-TODAY()<=2, "🟡 Por Vencer (≤48h)", "🟢 En Plazo")))))))
I54: =IF(B54="","",IF(H54<>"", H54-B54, TODAY()-B54)) | L54: =IF(B54="","", IF(ISNUMBER(SEARCH("Adjudicada / Ganada", K54)), "✅ Adjudicada", IF(ISNUMBER(SEARCH("No Adjudicada", K54)), "🔴 No Adjudicada", IF(OR(ISNUMBER(SEARCH("Declinada", K54)), ISNUMBER(SEARCH("No Enviada", J54))), "⚪ Declinada / No Cotizada", IF(ISNUMBER(SEARCH("Enviada", J54)), "📬 Cotización Enviada", IF(TODAY()>G54, "🔴 Atrasada / Vencida", IF(G54-TODAY()<=2, "🟡 Por Vencer (≤48h)", "🟢 En Plazo")))))))
I55: =IF(B55="","",IF(H55<>"", H55-B55, TODAY()-B55)) | L55: =IF(B55="","", IF(ISNUMBER(SEARCH("Adjudicada / Ganada", K55)), "✅ Adjudicada", IF(ISNUMBER(SEARCH("No Adjudicada", K55)), "🔴 No Adjudicada", IF(OR(ISNUMBER(SEARCH("Declinada", K55)), ISNUMBER(SEARCH("No Enviada", J55))), "⚪ Declinada / No Cotizada", IF(ISNUMBER(SEARCH("Enviada", J55)), "📬 Cotización Enviada", IF(TODAY()>G55, "🔴 Atrasada / Vencida", IF(G55-TODAY()<=2, "🟡 Por Vencer (≤48h)", "🟢 En Plazo")))))))
I56: =IF(B56="","",IF(H56<>"", H56-B56, TODAY()-B56)) | L56: =IF(B56="","", IF(ISNUMBER(SEARCH("Adjudicada / Ganada", K56)), "✅ Adjudicada", IF(ISNUMBER(SEARCH("No Adjudicada", K56)), "🔴 No Adjudicada", IF(OR(ISNUMBER(SEARCH("Declinada", K56)), ISNUMBER(SEARCH("No Enviada", J56))), "⚪ Declinada / No Cotizada", IF(ISNUMBER(SEARCH("Enviada", J56)), "📬 Cotización Enviada", IF(TODAY()>G56, "🔴 Atrasada / Vencida", IF(G56-TODAY()<=2, "🟡 Por Vencer (≤48h)", "🟢 En Plazo")))))))
I57: =IF(B57="","",IF(H57<>"", H57-B57, TODAY()-B57)) | L57: =IF(B57="","", IF(ISNUMBER(SEARCH("Adjudicada / Ganada", K57)), "✅ Adjudicada", IF(ISNUMBER(SEARCH("No Adjudicada", K57)), "🔴 No Adjudicada", IF(OR(ISNUMBER(SEARCH("Declinada", K57)), ISNUMBER(SEARCH("No Enviada", J57))), "⚪ Declinada / No Cotizada", IF(ISNUMBER(SEARCH("Enviada", J57)), "📬 Cotización Enviada", IF(TODAY()>G57, "🔴 Atrasada / Vencida", IF(G57-TODAY()<=2, "🟡 Por Vencer (≤48h)", "🟢 En Plazo")))))))
I58: =IF(B58="","",IF(H58<>"", H58-B58, TODAY()-B58)) | L58: =IF(B58="","", IF(ISNUMBER(SEARCH("Adjudicada / Ganada", K58)), "✅ Adjudicada", IF(ISNUMBER(SEARCH("No Adjudicada", K58)), "🔴 No Adjudicada", IF(OR(ISNUMBER(SEARCH("Declinada", K58)), ISNUMBER(SEARCH("No Enviada", J58))), "⚪ Declinada / No Cotizada", IF(ISNUMBER(SEARCH("Enviada", J58)), "📬 Cotización Enviada", IF(TODAY()>G58, "🔴 Atrasada / Vencida", IF(G58-TODAY()<=2, "🟡 Por Vencer (≤48h)", "🟢 En Plazo")))))))
I59: =IF(B59="","",IF(H59<>"", H59-B59, TODAY()-B59)) | L59: =IF(B59="","", IF(ISNUMBER(SEARCH("Adjudicada / Ganada", K59)), "✅ Adjudicada", IF(ISNUMBER(SEARCH("No Adjudicada", K59)), "🔴 No Adjudicada", IF(OR(ISNUMBER(SEARCH("Declinada", K59)), ISNUMBER(SEARCH("No Enviada", J59))), "⚪ Declinada / No Cotizada", IF(ISNUMBER(SEARCH("Enviada", J59)), "📬 Cotización Enviada", IF(TODAY()>G59, "🔴 Atrasada / Vencida", IF(G59-TODAY()<=2, "🟡 Por Vencer (≤48h)", "🟢 En Plazo")))))))
I60: =IF(B60="","",IF(H60<>"", H60-B60, TODAY()-B60)) | L60: =IF(B60="","", IF(ISNUMBER(SEARCH("Adjudicada / Ganada", K60)), "✅ Adjudicada", IF(ISNUMBER(SEARCH("No Adjudicada", K60)), "🔴 No Adjudicada", IF(OR(ISNUMBER(SEARCH("Declinada", K60)), ISNUMBER(SEARCH("No Enviada", J60))), "⚪ Declinada / No Cotizada", IF(ISNUMBER(SEARCH("Enviada", J60)), "📬 Cotización Enviada", IF(TODAY()>G60, "🔴 Atrasada / Vencida", IF(G60-TODAY()<=2, "🟡 Por Vencer (≤48h)", "🟢 En Plazo")))))))

Sheet 2. Control Flota y Taller
A1: GRUPO TERRACOP - DISPONIBILIDAD DE FLOTA Y CONTROL DE TALLER
A2: Pincha el check de la columna G para cambiar disponibilidad. Si está en taller, ingresa la fecha del Jefe de Taller.
A4: Item | B4: Cód. | C4: Patente | D4: Tipo de Equipo | E4: Modelo | F4: Ubicación Base | G4: CHECK ESTADO (PINCHA AQUÍ) | H4: Mandante Asignado (Si aplica) | I4: Fecha Entrada Taller | J4: Fecha Compromiso Taller | K4: Fecha Real Salida Taller | L4: Cumplimiento / Días Demora Taller | M4: ALERTA Y ESTADO AUTOMATIZADO
A5: 1 | B5: BZ-268 | C5: JTLJ-39 | D5: BULLDOZER | E5: CAT D8T | F5: FG COVER | G5: 🔵 EN USO POR MANDANTE | H5: FG COVER | L5: =IF(I5="","",IF(K5<>"",IF(--K5<=--J5,"🟢 Cumplido a Tiempo","🟡 Entregado con Atraso ("&TEXT(--K5---J5,"0")&" d)"),IF(J5="","🔴 Sin Fecha Compromiso",IF(TODAY()<=--J5,"🟢 En Plazo ("&TEXT(--J5-TODAY(),"0")&" d rest.)","🔴 Atrasado ("&TEXT(TODAY()---J5,"0")&" d)")))) | M5: =IF(G5="","", IF(ISNUMBER(SEARCH("DISPONIBLE", G5)), "🟢 DISPONIBLE INMEDIATO", IF(ISNUMBER(SEARCH("MANDANTE", G5)), IF(H5<>"","🔵 EN OPERACIÓN: " & H5,"🔵 EN OPERACIÓN"), IF(ISNUMBER(SEARCH("NO OPERATIVO", G5)), "🔴 NO OPERATIVO CRÍTICO", IF(K5<>"", "🟢 SALIÓ DE TALLER (DISPONIBLE)", IF(J5="", "🔴 EN TALLER (Falta Fecha Jefe Taller)", IF(TODAY()>J5, "🔴 DEMORA / RETRASO EN TALLER", IF(J5-TODAY()<=2, "🟡 YA POR SALIR DEL TALLER", "🟡 EN MANTENCIÓN SEGÚN PROGRAMA")))))))) -> 🔵 EN OPERACIÓN: FG COVER
A6: 2 | B6: BZ-332 | C6: RKCJ-17 | D6: BULLDOZER | E6: KOMATSU 155 | F6: FG COVER | G6: 🔵 EN USO POR MANDANTE | H6: FG COVER | L6: =IF(I6="","",IF(K6<>"",IF(--K6<=--J6,"🟢 Cumplido a Tiempo","🟡 Entregado con Atraso ("&TEXT(--K6---J6,"0")&" d)"),IF(J6="","🔴 Sin Fecha Compromiso",IF(TODAY()<=--J6,"🟢 En Plazo ("&TEXT(--J6-TODAY(),"0")&" d rest.)","🔴 Atrasado ("&TEXT(TODAY()---J6,"0")&" d)")))) | M6: =IF(G6="","", IF(ISNUMBER(SEARCH("DISPONIBLE", G6)), "🟢 DISPONIBLE INMEDIATO", IF(ISNUMBER(SEARCH("MANDANTE", G6)), IF(H6<>"","🔵 EN OPERACIÓN: " & H6,"🔵 EN OPERACIÓN"), IF(ISNUMBER(SEARCH("NO OPERATIVO", G6)), "🔴 NO OPERATIVO CRÍTICO", IF(K6<>"", "🟢 SALIÓ DE TALLER (DISPONIBLE)", IF(J6="", "🔴 EN TALLER (Falta Fecha Jefe Taller)", IF(TODAY()>J6, "🔴 DEMORA / RETRASO EN TALLER", IF(J6-TODAY()<=2, "🟡 YA POR SALIR DEL TALLER", "🟡 EN MANTENCIÓN SEGÚN PROGRAMA")))))))) -> 🔵 EN OPERACIÓN: FG COVER
A7: 3 | B7: CF-221 | C7: DHVC-64 | D7: CARGADOR FRONTAL | E7: CAT 962H | F7: FG COVER | G7: 🔵 EN USO POR MANDANTE | H7: FG COVER | L7: =IF(I7="","",IF(K7<>"",IF(--K7<=--J7,"🟢 Cumplido a Tiempo","🟡 Entregado con Atraso ("&TEXT(--K7---J7,"0")&" d)"),IF(J7="","🔴 Sin Fecha Compromiso",IF(TODAY()<=--J7,"🟢 En Plazo ("&TEXT(--J7-TODAY(),"0")&" d rest.)","🔴 Atrasado ("&TEXT(TODAY()---J7,"0")&" d)")))) | M7: =IF(G7="","", IF(ISNUMBER(SEARCH("DISPONIBLE", G7)), "🟢 DISPONIBLE INMEDIATO", IF(ISNUMBER(SEARCH("MANDANTE", G7)), IF(H7<>"","🔵 EN OPERACIÓN: " & H7,"🔵 EN OPERACIÓN"), IF(ISNUMBER(SEARCH("NO OPERATIVO", G7)), "🔴 NO OPERATIVO CRÍTICO", IF(K7<>"", "🟢 SALIÓ DE TALLER (DISPONIBLE)", IF(J7="", "🔴 EN TALLER (Falta Fecha Jefe Taller)", IF(TODAY()>J7, "🔴 DEMORA / RETRASO EN TALLER", IF(J7-TODAY()<=2, "🟡 YA POR SALIR DEL TALLER", "🟡 EN MANTENCIÓN SEGÚN PROGRAMA")))))))) -> 🔵 EN OPERACIÓN: FG COVER
A8: 4 | B8: CF-234 | C8: FSJX-90 | D8: CARGADOR FRONTAL | E8: CAT 966H | F8: FG COVER | G8: 🟢 DISPONIBLE INMEDIATO | H8: VIÑITA (Base Central) | L8: =IF(I8="","",IF(K8<>"",IF(--K8<=--J8,"🟢 Cumplido a Tiempo","🟡 Entregado con Atraso ("&TEXT(--K8---J8,"0")&" d)"),IF(J8="","🔴 Sin Fecha Compromiso",IF(TODAY()<=--J8,"🟢 En Plazo ("&TEXT(--J8-TODAY(),"0")&" d rest.)","🔴 Atrasado ("&TEXT(TODAY()---J8,"0")&" d)")))) | M8: =IF(G8="","", IF(ISNUMBER(SEARCH("DISPONIBLE", G8)), "🟢 DISPONIBLE INMEDIATO", IF(ISNUMBER(SEARCH("MANDANTE", G8)), IF(H8<>"","🔵 EN OPERACIÓN: " & H8,"🔵 EN OPERACIÓN"), IF(ISNUMBER(SEARCH("NO OPERATIVO", G8)), "🔴 NO OPERATIVO CRÍTICO", IF(K8<>"", "🟢 SALIÓ DE TALLER (DISPONIBLE)", IF(J8="", "🔴 EN TALLER (Falta Fecha Jefe Taller)", IF(TODAY()>J8, "🔴 DEMORA / RETRASO EN TALLER", IF(J8-TODAY()<=2, "🟡 YA POR SALIR DEL TALLER", "🟡 EN MANTENCIÓN SEGÚN PROGRAMA")))))))) -> 🟢 DISPONIBLE INMEDIATO
A9: 5 | B9: CF-308 | C9: GJDR-79 | D9: CARGADOR FRONTAL | E9: CAT 962H | F9: TALLER | G9: 🔵 EN USO POR MANDANTE | H9: FG COVER (Fenix Gold) | L9: =IF(I9="","",IF(K9<>"",IF(--K9<=--J9,"🟢 Cumplido a Tiempo","🟡 Entregado con Atraso ("&TEXT(--K9---J9,"0")&" d)"),IF(J9="","🔴 Sin Fecha Compromiso",IF(TODAY()<=--J9,"🟢 En Plazo ("&TEXT(--J9-TODAY(),"0")&" d rest.)","🔴 Atrasado ("&TEXT(TODAY()---J9,"0")&" d)")))) | M9: =IF(G9="","", IF(ISNUMBER(SEARCH("DISPONIBLE", G9)), "🟢 DISPONIBLE INMEDIATO", IF(ISNUMBER(SEARCH("MANDANTE", G9)), IF(H9<>"","🔵 EN OPERACIÓN: " & H9,"🔵 EN OPERACIÓN"), IF(ISNUMBER(SEARCH("NO OPERATIVO", G9)), "🔴 NO OPERATIVO CRÍTICO", IF(K9<>"", "🟢 SALIÓ DE TALLER (DISPONIBLE)", IF(J9="", "🔴 EN TALLER (Falta Fecha Jefe Taller)", IF(TODAY()>J9, "🔴 DEMORA / RETRASO EN TALLER", IF(J9-TODAY()<=2, "🟡 YA POR SALIR DEL TALLER", "🟡 EN MANTENCIÓN SEGÚN PROGRAMA")))))))) -> 🔵 EN OPERACIÓN: FG COVER (Fenix Gold)
A10: 6 | B10: EXC-206 | C10: HSZC-48 | D10: EXCAVADORA | E10: CAT 320D2L | F10: TALLER | G10: 🟡 EN TALLER / MANTENCIÓN | H10: TALLER | I10: 46267 | J10: 46276 | L10: =IF(I10="","",IF(K10<>"",IF(--K10<=--J10,"🟢 Cumplido a Tiempo","🟡 Entregado con Atraso ("&TEXT(--K10---J10,"0")&" d)"),IF(J10="","🔴 Sin Fecha Compromiso",IF(TODAY()<=--J10,"🟢 En Plazo ("&TEXT(--J10-TODAY(),"0")&" d rest.)","🔴 Atrasado ("&TEXT(TODAY()---J10,"0")&" d)")))) -> 🟢 En Plazo (7 d rest.) | M10: =IF(G10="","", IF(ISNUMBER(SEARCH("DISPONIBLE", G10)), "🟢 DISPONIBLE INMEDIATO", IF(ISNUMBER(SEARCH("MANDANTE", G10)), IF(H10<>"","🔵 EN OPERACIÓN: " & H10,"🔵 EN OPERACIÓN"), IF(ISNUMBER(SEARCH("NO OPERATIVO", G10)), "🔴 NO OPERATIVO CRÍTICO", IF(K10<>"", "🟢 SALIÓ DE TALLER (DISPONIBLE)", IF(J10="", "🔴 EN TALLER (Falta Fecha Jefe Taller)", IF(TODAY()>J10, "🔴 DEMORA / RETRASO EN TALLER", IF(J10-TODAY()<=2, "🟡 YA POR SALIR DEL TALLER", "🟡 EN MANTENCIÓN SEGÚN PROGRAMA")))))))) -> 🟡 EN MANTENCIÓN SEGÚN PROGRAMA
A11: 7 | B11: EXC-209 | C11: HYPS-60 | D11: EXCAVADORA | E11: CAT 320D2L | F11: F. GOLD | G11: 🔵 EN USO POR MANDANTE | H11: fenix Privados | L11: =IF(I11="","",IF(K11<>"",IF(--K11<=--J11,"🟢 Cumplido a Tiempo","🟡 Entregado con Atraso ("&TEXT(--K11---J11,"0")&" d)"),IF(J11="","🔴 Sin Fecha Compromiso",IF(TODAY()<=--J11,"🟢 En Plazo ("&TEXT(--J11-TODAY(),"0")&" d rest.)","🔴 Atrasado ("&TEXT(TODAY()---J11,"0")&" d)")))) | M11: =IF(G11="","", IF(ISNUMBER(SEARCH("DISPONIBLE", G11)), "🟢 DISPONIBLE INMEDIATO", IF(ISNUMBER(SEARCH("MANDANTE", G11)), IF(H11<>"","🔵 EN OPERACIÓN: " & H11,"🔵 EN OPERACIÓN"), IF(ISNUMBER(SEARCH("NO OPERATIVO", G11)), "🔴 NO OPERATIVO CRÍTICO", IF(K11<>"", "🟢 SALIÓ DE TALLER (DISPONIBLE)", IF(J11="", "🔴 EN TALLER (Falta Fecha Jefe Taller)", IF(TODAY()>J11, "🔴 DEMORA / RETRASO EN TALLER", IF(J11-TODAY()<=2, "🟡 YA POR SALIR DEL TALLER", "🟡 EN MANTENCIÓN SEGÚN PROGRAMA")))))))) -> 🔵 EN OPERACIÓN: fenix Privados
A12: 8 | B12: EXC-229 | C12: HSZC-45 | D12: EXCAVADORA | E12: CAT 320D2L | F12: FG COVER | G12: 🔵 EN USO POR MANDANTE | H12: FG COVER | L12: =IF(I12="","",IF(K12<>"",IF(--K12<=--J12,"🟢 Cumplido a Tiempo","🟡 Entregado con Atraso ("&TEXT(--K12---J12,"0")&" d)"),IF(J12="","🔴 Sin Fecha Compromiso",IF(TODAY()<=--J12,"🟢 En Plazo ("&TEXT(--J12-TODAY(),"0")&" d rest.)","🔴 Atrasado ("&TEXT(TODAY()---J12,"0")&" d)")))) | M12: =IF(G12="","", IF(ISNUMBER(SEARCH("DISPONIBLE", G12)), "🟢 DISPONIBLE INMEDIATO", IF(ISNUMBER(SEARCH("MANDANTE", G12)), IF(H12<>"","🔵 EN OPERACIÓN: " & H12,"🔵 EN OPERACIÓN"), IF(ISNUMBER(SEARCH("NO OPERATIVO", G12)), "🔴 NO OPERATIVO CRÍTICO", IF(K12<>"", "🟢 SALIÓ DE TALLER (DISPONIBLE)", IF(J12="", "🔴 EN TALLER (Falta Fecha Jefe Taller)", IF(TODAY()>J12, "🔴 DEMORA / RETRASO EN TALLER", IF(J12-TODAY()<=2, "🟡 YA POR SALIR DEL TALLER", "🟡 EN MANTENCIÓN SEGÚN PROGRAMA")))))))) -> 🔵 EN OPERACIÓN: FG COVER
A13: 9 | B13: EXC-301 | C13: KZGP-67 | D13: EXCAVADORA | E13: CAT 336D2L | F13: FG COVER | G13: 🔵 EN USO POR MANDANTE | H13: FG COVER | L13: =IF(I13="","",IF(K13<>"",IF(--K13<=--J13,"🟢 Cumplido a Tiempo","🟡 Entregado con Atraso ("&TEXT(--K13---J13,"0")&" d)"),IF(J13="","🔴 Sin Fecha Compromiso",IF(TODAY()<=--J13,"🟢 En Plazo ("&TEXT(--J13-TODAY(),"0")&" d rest.)","🔴 Atrasado ("&TEXT(TODAY()---J13,"0")&" d)")))) | M13: =IF(G13="","", IF(ISNUMBER(SEARCH("DISPONIBLE", G13)), "🟢 DISPONIBLE INMEDIATO", IF(ISNUMBER(SEARCH("MANDANTE", G13)), IF(H13<>"","🔵 EN OPERACIÓN: " & H13,"🔵 EN OPERACIÓN"), IF(ISNUMBER(SEARCH("NO OPERATIVO", G13)), "🔴 NO OPERATIVO CRÍTICO", IF(K13<>"", "🟢 SALIÓ DE TALLER (DISPONIBLE)", IF(J13="", "🔴 EN TALLER (Falta Fecha Jefe Taller)", IF(TODAY()>J13, "🔴 DEMORA / RETRASO EN TALLER", IF(J13-TODAY()<=2, "🟡 YA POR SALIR DEL TALLER", "🟡 EN MANTENCIÓN SEGÚN PROGRAMA")))))))) -> 🔵 EN OPERACIÓN: FG COVER
A14: 10 | B14: EXC-307 | C14: SIN PLACA | D14: EXCAVADORA | E14: CAT 349D | F14: TALLER | G14: 🟡 EN TALLER / MANTENCIÓN | H14: VIÑITA (Base Central) | I14: 46251 | J14: 46274 | L14: =IF(I14="","",IF(K14<>"",IF(--K14<=--J14,"🟢 Cumplido a Tiempo","🟡 Entregado con Atraso ("&TEXT(--K14---J14,"0")&" d)"),IF(J14="","🔴 Sin Fecha Compromiso",IF(TODAY()<=--J14,"🟢 En Plazo ("&TEXT(--J14-TODAY(),"0")&" d rest.)","🔴 Atrasado ("&TEXT(TODAY()---J14,"0")&" d)")))) -> 🟢 En Plazo (5 d rest.) | M14: =IF(G14="","", IF(ISNUMBER(SEARCH("DISPONIBLE", G14)), "🟢 DISPONIBLE INMEDIATO", IF(ISNUMBER(SEARCH("MANDANTE", G14)), IF(H14<>"","🔵 EN OPERACIÓN: " & H14,"🔵 EN OPERACIÓN"), IF(ISNUMBER(SEARCH("NO OPERATIVO", G14)), "🔴 NO OPERATIVO CRÍTICO", IF(K14<>"", "🟢 SALIÓ DE TALLER (DISPONIBLE)", IF(J14="", "🔴 EN TALLER (Falta Fecha Jefe Taller)", IF(TODAY()>J14, "🔴 DEMORA / RETRASO EN TALLER", IF(J14-TODAY()<=2, "🟡 YA POR SALIR DEL TALLER", "🟡 EN MANTENCIÓN SEGÚN PROGRAMA")))))))) -> 🟡 EN MANTENCIÓN SEGÚN PROGRAMA
A15: 11 | B15: MN-338 | C15: SJFB-61 | D15: MOTONIVELADORA | E15: CAT 150 M | F15: VIÑITA | G15: 🟢 DISPONIBLE INMEDIATO | H15: VIÑITA (Base Central) | M15: =IF(G15="","", IF(ISNUMBER(SEARCH("DISPONIBLE", G15)), "🟢 DISPONIBLE INMEDIATO", IF(ISNUMBER(SEARCH("MANDANTE", G15)), IF(H15<>"","🔵 EN OPERACIÓN: " & H15,"🔵 EN OPERACIÓN"), IF(ISNUMBER(SEARCH("NO OPERATIVO", G15)), "🔴 NO OPERATIVO CRÍTICO", IF(K15<>"", "🟢 SALIÓ DE TALLER (DISPONIBLE)", IF(J15="", "🔴 EN TALLER (Falta Fecha Jefe Taller)", IF(TODAY()>J15, "🔴 DEMORA / RETRASO EN TALLER", IF(J15-TODAY()<=2, "🟡 YA POR SALIR DEL TALLER", "🟡 EN MANTENCIÓN SEGÚN PROGRAMA")))))))) -> 🟢 DISPONIBLE INMEDIATO
A16: 12 | B16: MN-231 | C16: JDYW-89 | D16: MOTONIVELADORA | E16: CAT 140M | F16: VIÑITA | G16: 🟢 DISPONIBLE INMEDIATO | H16: VIÑITA (Base Central) | M16: =IF(G16="","", IF(ISNUMBER(SEARCH("DISPONIBLE", G16)), "🟢 DISPONIBLE INMEDIATO", IF(ISNUMBER(SEARCH("MANDANTE", G16)), IF(H16<>"","🔵 EN OPERACIÓN: " & H16,"🔵 EN OPERACIÓN"), IF(ISNUMBER(SEARCH("NO OPERATIVO", G16)), "🔴 NO OPERATIVO CRÍTICO", IF(K16<>"", "🟢 SALIÓ DE TALLER (DISPONIBLE)", IF(J16="", "🔴 EN TALLER (Falta Fecha Jefe Taller)", IF(TODAY()>J16, "🔴 DEMORA / RETRASO EN TALLER", IF(J16-TODAY()<=2, "🟡 YA POR SALIR DEL TALLER", "🟡 EN MANTENCIÓN SEGÚN PROGRAMA")))))))) -> 🟢 DISPONIBLE INMEDIATO
A17: 13 | B17: RT-169 | C17: CKZT-81 | D17: RETROEXCAVADORA | E17: CAT 416E | F17: TALLER | G17: 🔴 NO OPERATIVO / FUERA SERVICIO | H17: VIÑITA (Base Central) | L17: =IF(I17="","",IF(K17<>"",IF(--K17<=--J17,"🟢 Cumplido a Tiempo","🟡 Entregado con Atraso ("&TEXT(--K17---J17,"0")&" d)"),IF(J17="","🔴 Sin Fecha Compromiso",IF(TODAY()<=--J17,"🟢 En Plazo ("&TEXT(--J17-TODAY(),"0")&" d rest.)","🔴 Atrasado ("&TEXT(TODAY()---J17,"0")&" d)")))) | M17: =IF(G17="","", IF(ISNUMBER(SEARCH("DISPONIBLE", G17)), "🟢 DISPONIBLE INMEDIATO", IF(ISNUMBER(SEARCH("MANDANTE", G17)), IF(H17<>"","🔵 EN OPERACIÓN: " & H17,"🔵 EN OPERACIÓN"), IF(ISNUMBER(SEARCH("NO OPERATIVO", G17)), "🔴 NO OPERATIVO CRÍTICO", IF(K17<>"", "🟢 SALIÓ DE TALLER (DISPONIBLE)", IF(J17="", "🔴 EN TALLER (Falta Fecha Jefe Taller)", IF(TODAY()>J17, "🔴 DEMORA / RETRASO EN TALLER", IF(J17-TODAY()<=2, "🟡 YA POR SALIR DEL TALLER", "🟡 EN MANTENCIÓN SEGÚN PROGRAMA")))))))) -> 🔴 NO OPERATIVO CRÍTICO
A18: 14 | B18: RT-339 | C18: SSGZ-30 | D18: RETROEXCAVADORA | E18: CAT 416 | F18: VIÑITA | G18: 🟢 DISPONIBLE INMEDIATO | H18: VIÑITA (Base Central) | L18: =IF(I18="","",IF(K18<>"",IF(--K18<=--J18,"🟢 Cumplido a Tiempo","🟡 Entregado con Atraso ("&TEXT(--K18---J18,"0")&" d)"),IF(J18="","🔴 Sin Fecha Compromiso",IF(TODAY()<=--J18,"🟢 En Plazo ("&TEXT(--J18-TODAY(),"0")&" d rest.)","🔴 Atrasado ("&TEXT(TODAY()---J18,"0")&" d)")))) | M18: =IF(G18="","", IF(ISNUMBER(SEARCH("DISPONIBLE", G18)), "🟢 DISPONIBLE INMEDIATO", IF(ISNUMBER(SEARCH("MANDANTE", G18)), IF(H18<>"","🔵 EN OPERACIÓN: " & H18,"🔵 EN OPERACIÓN"), IF(ISNUMBER(SEARCH("NO OPERATIVO", G18)), "🔴 NO OPERATIVO CRÍTICO", IF(K18<>"", "🟢 SALIÓ DE TALLER (DISPONIBLE)", IF(J18="", "🔴 EN TALLER (Falta Fecha Jefe Taller)", IF(TODAY()>J18, "🔴 DEMORA / RETRASO EN TALLER", IF(J18-TODAY()<=2, "🟡 YA POR SALIR DEL TALLER", "🟡 EN MANTENCIÓN SEGÚN PROGRAMA")))))))) -> 🟢 DISPONIBLE INMEDIATO
A19: 15 | B19: RT-340 | C19: SSDC-16 | D19: RETROEXCAVADORA | E19: CAT 416 | F19: FG OOCC | G19: 🔵 EN USO POR MANDANTE | H19: FG OOCC | L19: =IF(I19="","",IF(K19<>"",IF(--K19<=--J19,"🟢 Cumplido a Tiempo","🟡 Entregado con Atraso ("&TEXT(--K19---J19,"0")&" d)"),IF(J19="","🔴 Sin Fecha Compromiso",IF(TODAY()<=--J19,"🟢 En Plazo ("&TEXT(--J19-TODAY(),"0")&" d rest.)","🔴 Atrasado ("&TEXT(TODAY()---J19,"0")&" d)")))) | M19: =IF(G19="","", IF(ISNUMBER(SEARCH("DISPONIBLE", G19)), "🟢 DISPONIBLE INMEDIATO", IF(ISNUMBER(SEARCH("MANDANTE", G19)), IF(H19<>"","🔵 EN OPERACIÓN: " & H19,"🔵 EN OPERACIÓN"), IF(ISNUMBER(SEARCH("NO OPERATIVO", G19)), "🔴 NO OPERATIVO CRÍTICO", IF(K19<>"", "🟢 SALIÓ DE TALLER (DISPONIBLE)", IF(J19="", "🔴 EN TALLER (Falta Fecha Jefe Taller)", IF(TODAY()>J19, "🔴 DEMORA / RETRASO EN TALLER", IF(J19-TODAY()<=2, "🟡 YA POR SALIR DEL TALLER", "🟡 EN MANTENCIÓN SEGÚN PROGRAMA")))))))) -> 🔵 EN OPERACIÓN: FG OOCC
A20: 16 | B20: MC-161 | C20: HHDG-52 | D20: MINICARGADOR | E20: CAT 236D | F20: TALLER | G20: 🟡 EN TALLER / MANTENCIÓN | H20: VIÑITA (Base Central) | L20: =IF(I20="","",IF(K20<>"",IF(--K20<=--J20,"🟢 Cumplido a Tiempo","🟡 Entregado con Atraso ("&TEXT(--K20---J20,"0")&" d)"),IF(J20="","🔴 Sin Fecha Compromiso",IF(TODAY()<=--J20,"🟢 En Plazo ("&TEXT(--J20-TODAY(),"0")&" d rest.)","🔴 Atrasado ("&TEXT(TODAY()---J20,"0")&" d)")))) | M20: =IF(G20="","", IF(ISNUMBER(SEARCH("DISPONIBLE", G20)), "🟢 DISPONIBLE INMEDIATO", IF(ISNUMBER(SEARCH("MANDANTE", G20)), IF(H20<>"","🔵 EN OPERACIÓN: " & H20,"🔵 EN OPERACIÓN"), IF(ISNUMBER(SEARCH("NO OPERATIVO", G20)), "🔴 NO OPERATIVO CRÍTICO", IF(K20<>"", "🟢 SALIÓ DE TALLER (DISPONIBLE)", IF(J20="", "🔴 EN TALLER (Falta Fecha Jefe Taller)", IF(TODAY()>J20, "🔴 DEMORA / RETRASO EN TALLER", IF(J20-TODAY()<=2, "🟡 YA POR SALIR DEL TALLER", "🟡 EN MANTENCIÓN SEGÚN PROGRAMA")))))))) -> 🔴 EN TALLER (Falta Fecha Jefe Taller)
A21: 17 | B21: MC-187 | C21: CYYS-75 | D21: MINICARGADOR | E21: CAT 236B3 | F21: VIÑITA | G21: 🟢 DISPONIBLE INMEDIATO | H21: VIÑITA (Base Central) | L21: =IF(I21="","",IF(K21<>"",IF(--K21<=--J21,"🟢 Cumplido a Tiempo","🟡 Entregado con Atraso ("&TEXT(--K21---J21,"0")&" d)"),IF(J21="","🔴 Sin Fecha Compromiso",IF(TODAY()<=--J21,"🟢 En Plazo ("&TEXT(--J21-TODAY(),"0")&" d rest.)","🔴 Atrasado ("&TEXT(TODAY()---J21,"0")&" d)")))) | M21: =IF(G21="","", IF(ISNUMBER(SEARCH("DISPONIBLE", G21)), "🟢 DISPONIBLE INMEDIATO", IF(ISNUMBER(SEARCH("MANDANTE", G21)), IF(H21<>"","🔵 EN OPERACIÓN: " & H21,"🔵 EN OPERACIÓN"), IF(ISNUMBER(SEARCH("NO OPERATIVO", G21)), "🔴 NO OPERATIVO CRÍTICO", IF(K21<>"", "🟢 SALIÓ DE TALLER (DISPONIBLE)", IF(J21="", "🔴 EN TALLER (Falta Fecha Jefe Taller)", IF(TODAY()>J21, "🔴 DEMORA / RETRASO EN TALLER", IF(J21-TODAY()<=2, "🟡 YA POR SALIR DEL TALLER", "🟡 EN MANTENCIÓN SEGÚN PROGRAMA")))))))) -> 🟢 DISPONIBLE INMEDIATO
A22: 18 | B22: ROD-320 | C22: PSJW-22 | D22: RODILLO 12TON | E22: JCB 116HL | F22: VIÑITA | G22: 🟢 DISPONIBLE INMEDIATO | H22: VIÑITA (Base Central) | L22: =IF(I22="","",IF(K22<>"",IF(--K22<=--J22,"🟢 Cumplido a Tiempo","🟡 Entregado con Atraso ("&TEXT(--K22---J22,"0")&" d)"),IF(J22="","🔴 Sin Fecha Compromiso",IF(TODAY()<=--J22,"🟢 En Plazo ("&TEXT(--J22-TODAY(),"0")&" d rest.)","🔴 Atrasado ("&TEXT(TODAY()---J22,"0")&" d)")))) | M22: =IF(G22="","", IF(ISNUMBER(SEARCH("DISPONIBLE", G22)), "🟢 DISPONIBLE INMEDIATO", IF(ISNUMBER(SEARCH("MANDANTE", G22)), IF(H22<>"","🔵 EN OPERACIÓN: " & H22,"🔵 EN OPERACIÓN"), IF(ISNUMBER(SEARCH("NO OPERATIVO", G22)), "🔴 NO OPERATIVO CRÍTICO", IF(K22<>"", "🟢 SALIÓ DE TALLER (DISPONIBLE)", IF(J22="", "🔴 EN TALLER (Falta Fecha Jefe Taller)", IF(TODAY()>J22, "🔴 DEMORA / RETRASO EN TALLER", IF(J22-TODAY()<=2, "🟡 YA POR SALIR DEL TALLER", "🟡 EN MANTENCIÓN SEGÚN PROGRAMA")))))))) -> 🟢 DISPONIBLE INMEDIATO
A23: 19 | B23: PTA-329 | C23: PTA-329 | D23: PLANTA SELECCIONADORA | E23: KLEMANN MS702 | F23: FG COVER | G23: 🔵 EN USO POR MANDANTE | H23: FG COVER (Fenix Gold) | L23: =IF(I23="","",IF(K23<>"",IF(--K23<=--J23,"🟢 Cumplido a Tiempo","🟡 Entregado con Atraso ("&TEXT(--K23---J23,"0")&" d)"),IF(J23="","🔴 Sin Fecha Compromiso",IF(TODAY()<=--J23,"🟢 En Plazo ("&TEXT(--J23-TODAY(),"0")&" d rest.)","🔴 Atrasado ("&TEXT(TODAY()---J23,"0")&" d)")))) | M23: =IF(G23="","", IF(ISNUMBER(SEARCH("DISPONIBLE", G23)), "🟢 DISPONIBLE INMEDIATO", IF(ISNUMBER(SEARCH("MANDANTE", G23)), IF(H23<>"","🔵 EN OPERACIÓN: " & H23,"🔵 EN OPERACIÓN"), IF(ISNUMBER(SEARCH("NO OPERATIVO", G23)), "🔴 NO OPERATIVO CRÍTICO", IF(K23<>"", "🟢 SALIÓ DE TALLER (DISPONIBLE)", IF(J23="", "🔴 EN TALLER (Falta Fecha Jefe Taller)", IF(TODAY()>J23, "🔴 DEMORA / RETRASO EN TALLER", IF(J23-TODAY()<=2, "🟡 YA POR SALIR DEL TALLER", "🟡 EN MANTENCIÓN SEGÚN PROGRAMA")))))))) -> 🔵 EN OPERACIÓN: FG COVER (Fenix Gold)
A24: 20 | B24: PTA-364 | C24: PTA-364 | D24: PLANTA SELECCIONADORA | E24: KLEMANN MS802 | F24: FG COVER | G24: 🔴 NO OPERATIVO / FUERA SERVICIO | H24: FG COVER (Fenix Gold) | L24: =IF(I24="","",IF(K24<>"",IF(--K24<=--J24,"🟢 Cumplido a Tiempo","🟡 Entregado con Atraso ("&TEXT(--K24---J24,"0")&" d)"),IF(J24="","🔴 Sin Fecha Compromiso",IF(TODAY()<=--J24,"🟢 En Plazo ("&TEXT(--J24-TODAY(),"0")&" d rest.)","🔴 Atrasado ("&TEXT(TODAY()---J24,"0")&" d)")))) | M24: =IF(G24="","", IF(ISNUMBER(SEARCH("DISPONIBLE", G24)), "🟢 DISPONIBLE INMEDIATO", IF(ISNUMBER(SEARCH("MANDANTE", G24)), IF(H24<>"","🔵 EN OPERACIÓN: " & H24,"🔵 EN OPERACIÓN"), IF(ISNUMBER(SEARCH("NO OPERATIVO", G24)), "🔴 NO OPERATIVO CRÍTICO", IF(K24<>"", "🟢 SALIÓ DE TALLER (DISPONIBLE)", IF(J24="", "🔴 EN TALLER (Falta Fecha Jefe Taller)", IF(TODAY()>J24, "🔴 DEMORA / RETRASO EN TALLER", IF(J24-TODAY()<=2, "🟡 YA POR SALIR DEL TALLER", "🟡 EN MANTENCIÓN SEGÚN PROGRAMA")))))))) -> 🔴 NO OPERATIVO CRÍTICO
A25: 21 | B25: MS14Z | C25: MS14Z | D25: PLANTA SELECCIONADORA | E25: MS 14Z KLEMANN | F25: FG COVER | G25: 🔵 EN USO POR MANDANTE | H25: FG COVER | L25: =IF(I25="","",IF(K25<>"",IF(--K25<=--J25,"🟢 Cumplido a Tiempo","🟡 Entregado con Atraso ("&TEXT(--K25---J25,"0")&" d)"),IF(J25="","🔴 Sin Fecha Compromiso",IF(TODAY()<=--J25,"🟢 En Plazo ("&TEXT(--J25-TODAY(),"0")&" d rest.)","🔴 Atrasado ("&TEXT(TODAY()---J25,"0")&" d)")))) | M25: =IF(G25="","", IF(ISNUMBER(SEARCH("DISPONIBLE", G25)), "🟢 DISPONIBLE INMEDIATO", IF(ISNUMBER(SEARCH("MANDANTE", G25)), IF(H25<>"","🔵 EN OPERACIÓN: " & H25,"🔵 EN OPERACIÓN"), IF(ISNUMBER(SEARCH("NO OPERATIVO", G25)), "🔴 NO OPERATIVO CRÍTICO", IF(K25<>"", "🟢 SALIÓ DE TALLER (DISPONIBLE)", IF(J25="", "🔴 EN TALLER (Falta Fecha Jefe Taller)", IF(TODAY()>J25, "🔴 DEMORA / RETRASO EN TALLER", IF(J25-TODAY()<=2, "🟡 YA POR SALIR DEL TALLER", "🟡 EN MANTENCIÓN SEGÚN PROGRAMA")))))))) -> 🔵 EN OPERACIÓN: FG COVER
A26: 22 | B26: TC-171 | C26: GHCC-98 | D26: TRACTO CAMION | E26: MACK CXU613E | F26: TALLER | G26: 🔴 NO OPERATIVO / FUERA SERVICIO | H26: TRANSPORTE | I26: 46261 | J26: 46274 | L26: =IF(I26="","",IF(K26<>"",IF(--K26<=--J26,"🟢 Cumplido a Tiempo","🟡 Entregado con Atraso ("&TEXT(--K26---J26,"0")&" d)"),IF(J26="","🔴 Sin Fecha Compromiso",IF(TODAY()<=--J26,"🟢 En Plazo ("&TEXT(--J26-TODAY(),"0")&" d rest.)","🔴 Atrasado ("&TEXT(TODAY()---J26,"0")&" d)")))) -> 🟢 En Plazo (5 d rest.) | M26: =IF(G26="","", IF(ISNUMBER(SEARCH("DISPONIBLE", G26)), "🟢 DISPONIBLE INMEDIATO", IF(ISNUMBER(SEARCH("MANDANTE", G26)), IF(H26<>"","🔵 EN OPERACIÓN: " & H26,"🔵 EN OPERACIÓN"), IF(ISNUMBER(SEARCH("NO OPERATIVO", G26)), "🔴 NO OPERATIVO CRÍTICO", IF(K26<>"", "🟢 SALIÓ DE TALLER (DISPONIBLE)", IF(J26="", "🔴 EN TALLER (Falta Fecha Jefe Taller)", IF(TODAY()>J26, "🔴 DEMORA / RETRASO EN TALLER", IF(J26-TODAY()<=2, "🟡 YA POR SALIR DEL TALLER", "🟡 EN MANTENCIÓN SEGÚN PROGRAMA")))))))) -> 🔴 NO OPERATIVO CRÍTICO
A27: 23 | B27: TC-305 | C27: LPKL-45 | D27: TRACTO CAMION | E27: KENWORTH T880 | F27: TRANSPORTE | G27: 🔵 EN USO POR MANDANTE | H27: TRANSPORTE | L27: =IF(I27="","",IF(K27<>"",IF(--K27<=--J27,"🟢 Cumplido a Tiempo","🟡 Entregado con Atraso ("&TEXT(--K27---J27,"0")&" d)"),IF(J27="","🔴 Sin Fecha Compromiso",IF(TODAY()<=--J27,"🟢 En Plazo ("&TEXT(--J27-TODAY(),"0")&" d rest.)","🔴 Atrasado ("&TEXT(TODAY()---J27,"0")&" d)")))) | M27: =IF(G27="","", IF(ISNUMBER(SEARCH("DISPONIBLE", G27)), "🟢 DISPONIBLE INMEDIATO", IF(ISNUMBER(SEARCH("MANDANTE", G27)), IF(H27<>"","🔵 EN OPERACIÓN: " & H27,"🔵 EN OPERACIÓN"), IF(ISNUMBER(SEARCH("NO OPERATIVO", G27)), "🔴 NO OPERATIVO CRÍTICO", IF(K27<>"", "🟢 SALIÓ DE TALLER (DISPONIBLE)", IF(J27="", "🔴 EN TALLER (Falta Fecha Jefe Taller)", IF(TODAY()>J27, "🔴 DEMORA / RETRASO EN TALLER", IF(J27-TODAY()<=2, "🟡 YA POR SALIR DEL TALLER", "🟡 EN MANTENCIÓN SEGÚN PROGRAMA")))))))) -> 🔵 EN OPERACIÓN: TRANSPORTE
A28: 24 | B28: TC-333 | C28: RKFZ-49 | D28: TRACTO CAMION | E28: KENWORTH T880 MX13 | F28: TALLER | G28: 🔴 NO OPERATIVO / FUERA SERVICIO | H28: TRANSPORTE | I28: 46261 | J28: 46275 | L28: =IF(I28="","",IF(K28<>"",IF(--K28<=--J28,"🟢 Cumplido a Tiempo","🟡 Entregado con Atraso ("&TEXT(--K28---J28,"0")&" d)"),IF(J28="","🔴 Sin Fecha Compromiso",IF(TODAY()<=--J28,"🟢 En Plazo ("&TEXT(--J28-TODAY(),"0")&" d rest.)","🔴 Atrasado ("&TEXT(TODAY()---J28,"0")&" d)")))) -> 🟢 En Plazo (6 d rest.) | M28: =IF(G28="","", IF(ISNUMBER(SEARCH("DISPONIBLE", G28)), "🟢 DISPONIBLE INMEDIATO", IF(ISNUMBER(SEARCH("MANDANTE", G28)), IF(H28<>"","🔵 EN OPERACIÓN: " & H28,"🔵 EN OPERACIÓN"), IF(ISNUMBER(SEARCH("NO OPERATIVO", G28)), "🔴 NO OPERATIVO CRÍTICO", IF(K28<>"", "🟢 SALIÓ DE TALLER (DISPONIBLE)", IF(J28="", "🔴 EN TALLER (Falta Fecha Jefe Taller)", IF(TODAY()>J28, "🔴 DEMORA / RETRASO EN TALLER", IF(J28-TODAY()<=2, "🟡 YA POR SALIR DEL TALLER", "🟡 EN MANTENCIÓN SEGÚN PROGRAMA")))))))) -> 🔴 NO OPERATIVO CRÍTICO
A29: 25 | B29: TC-334 | C29: RKFZ-50 | D29: TRACTO CAMION | E29: KENWORTH T880 | F29: TALLER | G29: 🔴 NO OPERATIVO / FUERA SERVICIO | H29: TRANSPORTE | I29: 46268 | J29: 46276 | L29: =IF(I29="","",IF(K29<>"",IF(--K29<=--J29,"🟢 Cumplido a Tiempo","🟡 Entregado con Atraso ("&TEXT(--K29---J29,"0")&" d)"),IF(J29="","🔴 Sin Fecha Compromiso",IF(TODAY()<=--J29,"🟢 En Plazo ("&TEXT(--J29-TODAY(),"0")&" d rest.)","🔴 Atrasado ("&TEXT(TODAY()---J29,"0")&" d)")))) -> 🟢 En Plazo (7 d rest.) | M29: =IF(G29="","", IF(ISNUMBER(SEARCH("DISPONIBLE", G29)), "🟢 DISPONIBLE INMEDIATO", IF(ISNUMBER(SEARCH("MANDANTE", G29)), IF(H29<>"","🔵 EN OPERACIÓN: " & H29,"🔵 EN OPERACIÓN"), IF(ISNUMBER(SEARCH("NO OPERATIVO", G29)), "🔴 NO OPERATIVO CRÍTICO", IF(K29<>"", "🟢 SALIÓ DE TALLER (DISPONIBLE)", IF(J29="", "🔴 EN TALLER (Falta Fecha Jefe Taller)", IF(TODAY()>J29, "🔴 DEMORA / RETRASO EN TALLER", IF(J29-TODAY()<=2, "🟡 YA POR SALIR DEL TALLER", "🟡 EN MANTENCIÓN SEGÚN PROGRAMA")))))))) -> 🔴 NO OPERATIVO CRÍTICO
A30: 26 | B30: TC-351 | C30: TYLS-95 | D30: TRACTO CAMION | E30: MACK AN64TX | F30: TRANSPORTE | G30: 🔵 EN USO POR MANDANTE | H30: TRANSPORTE | L30: =IF(I30="","",IF(K30<>"",IF(--K30<=--J30,"🟢 Cumplido a Tiempo","🟡 Entregado con Atraso ("&TEXT(--K30---J30,"0")&" d)"),IF(J30="","🔴 Sin Fecha Compromiso",IF(TODAY()<=--J30,"🟢 En Plazo ("&TEXT(--J30-TODAY(),"0")&" d rest.)","🔴 Atrasado ("&TEXT(TODAY()---J30,"0")&" d)")))) | M30: =IF(G30="","", IF(ISNUMBER(SEARCH("DISPONIBLE", G30)), "🟢 DISPONIBLE INMEDIATO", IF(ISNUMBER(SEARCH("MANDANTE", G30)), IF(H30<>"","🔵 EN OPERACIÓN: " & H30,"🔵 EN OPERACIÓN"), IF(ISNUMBER(SEARCH("NO OPERATIVO", G30)), "🔴 NO OPERATIVO CRÍTICO", IF(K30<>"", "🟢 SALIÓ DE TALLER (DISPONIBLE)", IF(J30="", "🔴 EN TALLER (Falta Fecha Jefe Taller)", IF(TODAY()>J30, "🔴 DEMORA / RETRASO EN TALLER", IF(J30-TODAY()<=2, "🟡 YA POR SALIR DEL TALLER", "🟡 EN MANTENCIÓN SEGÚN PROGRAMA")))))))) -> 🔵 EN OPERACIÓN: TRANSPORTE
A31: 27 | B31: TC-357 | C31: VGBS-25 | D31: TRACTO CAMION | E31: SCANIA 500 A6X4NA | F31: TRANSPORTE | G31: 🔵 EN USO POR MANDANTE | H31: TRANSPORTE | L31: =IF(I31="","",IF(K31<>"",IF(--K31<=--J31,"🟢 Cumplido a Tiempo","🟡 Entregado con Atraso ("&TEXT(--K31---J31,"0")&" d)"),IF(J31="","🔴 Sin Fecha Compromiso",IF(TODAY()<=--J31,"🟢 En Plazo ("&TEXT(--J31-TODAY(),"0")&" d rest.)","🔴 Atrasado ("&TEXT(TODAY()---J31,"0")&" d)")))) | M31: =IF(G31="","", IF(ISNUMBER(SEARCH("DISPONIBLE", G31)), "🟢 DISPONIBLE INMEDIATO", IF(ISNUMBER(SEARCH("MANDANTE", G31)), IF(H31<>"","🔵 EN OPERACIÓN: " & H31,"🔵 EN OPERACIÓN"), IF(ISNUMBER(SEARCH("NO OPERATIVO", G31)), "🔴 NO OPERATIVO CRÍTICO", IF(K31<>"", "🟢 SALIÓ DE TALLER (DISPONIBLE)", IF(J31="", "🔴 EN TALLER (Falta Fecha Jefe Taller)", IF(TODAY()>J31, "🔴 DEMORA / RETRASO EN TALLER", IF(J31-TODAY()<=2, "🟡 YA POR SALIR DEL TALLER", "🟡 EN MANTENCIÓN SEGÚN PROGRAMA")))))))) -> 🔵 EN OPERACIÓN: TRANSPORTE
A32: 28 | B32: TC-358 | C32: VFRD-68 | D32: TRACTO CAMION | E32: SCANIA 500 A6X4NA | F32: TRANSPORTE | G32: 🔵 EN USO POR MANDANTE | H32: TRANSPORTE | L32: =IF(I32="","",IF(K32<>"",IF(--K32<=--J32,"🟢 Cumplido a Tiempo","🟡 Entregado con Atraso ("&TEXT(--K32---J32,"0")&" d)"),IF(J32="","🔴 Sin Fecha Compromiso",IF(TODAY()<=--J32,"🟢 En Plazo ("&TEXT(--J32-TODAY(),"0")&" d rest.)","🔴 Atrasado ("&TEXT(TODAY()---J32,"0")&" d)")))) | M32: =IF(G32="","", IF(ISNUMBER(SEARCH("DISPONIBLE", G32)), "🟢 DISPONIBLE INMEDIATO", IF(ISNUMBER(SEARCH("MANDANTE", G32)), IF(H32<>"","🔵 EN OPERACIÓN: " & H32,"🔵 EN OPERACIÓN"), IF(ISNUMBER(SEARCH("NO OPERATIVO", G32)), "🔴 NO OPERATIVO CRÍTICO", IF(K32<>"", "🟢 SALIÓ DE TALLER (DISPONIBLE)", IF(J32="", "🔴 EN TALLER (Falta Fecha Jefe Taller)", IF(TODAY()>J32, "🔴 DEMORA / RETRASO EN TALLER", IF(J32-TODAY()<=2, "🟡 YA POR SALIR DEL TALLER", "🟡 EN MANTENCIÓN SEGÚN PROGRAMA")))))))) -> 🔵 EN OPERACIÓN: TRANSPORTE
A33: 29 | B33: TC-359 | C33: VFRD-69 | D33: TRACTO CAMION | E33: SCANIA 500 A6X4NA | F33: TRANSPORTE | G33: 🔵 EN USO POR MANDANTE | H33: TRANSPORTE | L33: =IF(I33="","",IF(K33<>"",IF(--K33<=--J33,"🟢 Cumplido a Tiempo","🟡 Entregado con Atraso ("&TEXT(--K33---J33,"0")&" d)"),IF(J33="","🔴 Sin Fecha Compromiso",IF(TODAY()<=--J33,"🟢 En Plazo ("&TEXT(--J33-TODAY(),"0")&" d rest.)","🔴 Atrasado ("&TEXT(TODAY()---J33,"0")&" d)")))) | M33: =IF(G33="","", IF(ISNUMBER(SEARCH("DISPONIBLE", G33)), "🟢 DISPONIBLE INMEDIATO", IF(ISNUMBER(SEARCH("MANDANTE", G33)), IF(H33<>"","🔵 EN OPERACIÓN: " & H33,"🔵 EN OPERACIÓN"), IF(ISNUMBER(SEARCH("NO OPERATIVO", G33)), "🔴 NO OPERATIVO CRÍTICO", IF(K33<>"", "🟢 SALIÓ DE TALLER (DISPONIBLE)", IF(J33="", "🔴 EN TALLER (Falta Fecha Jefe Taller)", IF(TODAY()>J33, "🔴 DEMORA / RETRASO EN TALLER", IF(J33-TODAY()<=2, "🟡 YA POR SALIR DEL TALLER", "🟡 EN MANTENCIÓN SEGÚN PROGRAMA")))))))) -> 🔵 EN OPERACIÓN: TRANSPORTE
A34: 30 | B34: TC-360 | C34: VGHG-21 | D34: TRACTO CAMION | E34: SCANIA 500 A6X4NA | F34: TRANSPORTE | G34: 🔵 EN USO POR MANDANTE | H34: TRANSPORTE | L34: =IF(I34="","",IF(K34<>"",IF(--K34<=--J34,"🟢 Cumplido a Tiempo","🟡 Entregado con Atraso ("&TEXT(--K34---J34,"0")&" d)"),IF(J34="","🔴 Sin Fecha Compromiso",IF(TODAY()<=--J34,"🟢 En Plazo ("&TEXT(--J34-TODAY(),"0")&" d rest.)","🔴 Atrasado ("&TEXT(TODAY()---J34,"0")&" d)")))) | M34: =IF(G34="","", IF(ISNUMBER(SEARCH("DISPONIBLE", G34)), "🟢 DISPONIBLE INMEDIATO", IF(ISNUMBER(SEARCH("MANDANTE", G34)), IF(H34<>"","🔵 EN OPERACIÓN: " & H34,"🔵 EN OPERACIÓN"), IF(ISNUMBER(SEARCH("NO OPERATIVO", G34)), "🔴 NO OPERATIVO CRÍTICO", IF(K34<>"", "🟢 SALIÓ DE TALLER (DISPONIBLE)", IF(J34="", "🔴 EN TALLER (Falta Fecha Jefe Taller)", IF(TODAY()>J34, "🔴 DEMORA / RETRASO EN TALLER", IF(J34-TODAY()<=2, "🟡 YA POR SALIR DEL TALLER", "🟡 EN MANTENCIÓN SEGÚN PROGRAMA")))))))) -> 🔵 EN OPERACIÓN: TRANSPORTE
A35: 31 | B35: TC-361 | C35: VGGV-38 | D35: TRACTO CAMION | E35: SCANIA 500 A6X4NA | F35: TRANSPORTE | G35: 🔵 EN USO POR MANDANTE | H35: TRANSPORTE | L35: =IF(I35="","",IF(K35<>"",IF(--K35<=--J35,"🟢 Cumplido a Tiempo","🟡 Entregado con Atraso ("&TEXT(--K35---J35,"0")&" d)"),IF(J35="","🔴 Sin Fecha Compromiso",IF(TODAY()<=--J35,"🟢 En Plazo ("&TEXT(--J35-TODAY(),"0")&" d rest.)","🔴 Atrasado ("&TEXT(TODAY()---J35,"0")&" d)")))) | M35: =IF(G35="","", IF(ISNUMBER(SEARCH("DISPONIBLE", G35)), "🟢 DISPONIBLE INMEDIATO", IF(ISNUMBER(SEARCH("MANDANTE", G35)), IF(H35<>"","🔵 EN OPERACIÓN: " & H35,"🔵 EN OPERACIÓN"), IF(ISNUMBER(SEARCH("NO OPERATIVO", G35)), "🔴 NO OPERATIVO CRÍTICO", IF(K35<>"", "🟢 SALIÓ DE TALLER (DISPONIBLE)", IF(J35="", "🔴 EN TALLER (Falta Fecha Jefe Taller)", IF(TODAY()>J35, "🔴 DEMORA / RETRASO EN TALLER", IF(J35-TODAY()<=2, "🟡 YA POR SALIR DEL TALLER", "🟡 EN MANTENCIÓN SEGÚN PROGRAMA")))))))) -> 🔵 EN OPERACIÓN: TRANSPORTE
A36: 32 | B36: CT-172 | C36: GGZT-66 | D36: CAMION TOLVA | E36: MBENZ 4144k 2014 | F36: VIÑITA | G36: 🟢 DISPONIBLE INMEDIATO | H36: VIÑITA (Base Central) | L36: =IF(I36="","",IF(K36<>"",IF(--K36<=--J36,"🟢 Cumplido a Tiempo","🟡 Entregado con Atraso ("&TEXT(--K36---J36,"0")&" d)"),IF(J36="","🔴 Sin Fecha Compromiso",IF(TODAY()<=--J36,"🟢 En Plazo ("&TEXT(--J36-TODAY(),"0")&" d rest.)","🔴 Atrasado ("&TEXT(TODAY()---J36,"0")&" d)")))) | M36: =IF(G36="","", IF(ISNUMBER(SEARCH("DISPONIBLE", G36)), "🟢 DISPONIBLE INMEDIATO", IF(ISNUMBER(SEARCH("MANDANTE", G36)), IF(H36<>"","🔵 EN OPERACIÓN: " & H36,"🔵 EN OPERACIÓN"), IF(ISNUMBER(SEARCH("NO OPERATIVO", G36)), "🔴 NO OPERATIVO CRÍTICO", IF(K36<>"", "🟢 SALIÓ DE TALLER (DISPONIBLE)", IF(J36="", "🔴 EN TALLER (Falta Fecha Jefe Taller)", IF(TODAY()>J36, "🔴 DEMORA / RETRASO EN TALLER", IF(J36-TODAY()<=2, "🟡 YA POR SALIR DEL TALLER", "🟡 EN MANTENCIÓN SEGÚN PROGRAMA")))))))) -> 🟢 DISPONIBLE INMEDIATO
A37: 33 | B37: CT-174 | C37: GGZT-65 | D37: CAMION TOLVA | E37: MBENZ 4144k 2014 | F37: VIÑITA | G37: 🟢 DISPONIBLE INMEDIATO | H37: VIÑITA (Base Central) | L37: =IF(I37="","",IF(K37<>"",IF(--K37<=--J37,"🟢 Cumplido a Tiempo","🟡 Entregado con Atraso ("&TEXT(--K37---J37,"0")&" d)"),IF(J37="","🔴 Sin Fecha Compromiso",IF(TODAY()<=--J37,"🟢 En Plazo ("&TEXT(--J37-TODAY(),"0")&" d rest.)","🔴 Atrasado ("&TEXT(TODAY()---J37,"0")&" d)")))) | M37: =IF(G37="","", IF(ISNUMBER(SEARCH("DISPONIBLE", G37)), "🟢 DISPONIBLE INMEDIATO", IF(ISNUMBER(SEARCH("MANDANTE", G37)), IF(H37<>"","🔵 EN OPERACIÓN: " & H37,"🔵 EN OPERACIÓN"), IF(ISNUMBER(SEARCH("NO OPERATIVO", G37)), "🔴 NO OPERATIVO CRÍTICO", IF(K37<>"", "🟢 SALIÓ DE TALLER (DISPONIBLE)", IF(J37="", "🔴 EN TALLER (Falta Fecha Jefe Taller)", IF(TODAY()>J37, "🔴 DEMORA / RETRASO EN TALLER", IF(J37-TODAY()<=2, "🟡 YA POR SALIR DEL TALLER", "🟡 EN MANTENCIÓN SEGÚN PROGRAMA")))))))) -> 🟢 DISPONIBLE INMEDIATO
A38: 34 | B38: CT-180 | C38: GZXV-99 | D38: CAMION TOLVA | E38: MBENZ 4144k 2015 | F38: VIÑITA | G38: 🟢 DISPONIBLE INMEDIATO | H38: VIÑITA (Base Central) | L38: =IF(I38="","",IF(K38<>"",IF(--K38<=--J38,"🟢 Cumplido a Tiempo","🟡 Entregado con Atraso ("&TEXT(--K38---J38,"0")&" d)"),IF(J38="","🔴 Sin Fecha Compromiso",IF(TODAY()<=--J38,"🟢 En Plazo ("&TEXT(--J38-TODAY(),"0")&" d rest.)","🔴 Atrasado ("&TEXT(TODAY()---J38,"0")&" d)")))) | M38: =IF(G38="","", IF(ISNUMBER(SEARCH("DISPONIBLE", G38)), "🟢 DISPONIBLE INMEDIATO", IF(ISNUMBER(SEARCH("MANDANTE", G38)), IF(H38<>"","🔵 EN OPERACIÓN: " & H38,"🔵 EN OPERACIÓN"), IF(ISNUMBER(SEARCH("NO OPERATIVO", G38)), "🔴 NO OPERATIVO CRÍTICO", IF(K38<>"", "🟢 SALIÓ DE TALLER (DISPONIBLE)", IF(J38="", "🔴 EN TALLER (Falta Fecha Jefe Taller)", IF(TODAY()>J38, "🔴 DEMORA / RETRASO EN TALLER", IF(J38-TODAY()<=2, "🟡 YA POR SALIR DEL TALLER", "🟡 EN MANTENCIÓN SEGÚN PROGRAMA")))))))) -> 🟢 DISPONIBLE INMEDIATO
A39: 35 | B39: CT-365 | C39: VZPD-95 | D39: CAMION TOLVA | E39: SCANIA | F39: FG COVER | G39: 🔵 EN USO POR MANDANTE | H39: FG COVER (Fenix Gold) | L39: =IF(I39="","",IF(K39<>"",IF(--K39<=--J39,"🟢 Cumplido a Tiempo","🟡 Entregado con Atraso ("&TEXT(--K39---J39,"0")&" d)"),IF(J39="","🔴 Sin Fecha Compromiso",IF(TODAY()<=--J39,"🟢 En Plazo ("&TEXT(--J39-TODAY(),"0")&" d rest.)","🔴 Atrasado ("&TEXT(TODAY()---J39,"0")&" d)")))) | M39: =IF(G39="","", IF(ISNUMBER(SEARCH("DISPONIBLE", G39)), "🟢 DISPONIBLE INMEDIATO", IF(ISNUMBER(SEARCH("MANDANTE", G39)), IF(H39<>"","🔵 EN OPERACIÓN: " & H39,"🔵 EN OPERACIÓN"), IF(ISNUMBER(SEARCH("NO OPERATIVO", G39)), "🔴 NO OPERATIVO CRÍTICO", IF(K39<>"", "🟢 SALIÓ DE TALLER (DISPONIBLE)", IF(J39="", "🔴 EN TALLER (Falta Fecha Jefe Taller)", IF(TODAY()>J39, "🔴 DEMORA / RETRASO EN TALLER", IF(J39-TODAY()<=2, "🟡 YA POR SALIR DEL TALLER", "🟡 EN MANTENCIÓN SEGÚN PROGRAMA")))))))) -> 🔵 EN OPERACIÓN: FG COVER (Fenix Gold)
A40: 36 | B40: CT-366 | C40: VZPF-15 | D40: CAMION TOLVA | E40: SCANIA | F40: FG COVER | G40: 🔵 EN USO POR MANDANTE | H40: FG COVER (Fenix Gold) | L40: =IF(I40="","",IF(K40<>"",IF(--K40<=--J40,"🟢 Cumplido a Tiempo","🟡 Entregado con Atraso ("&TEXT(--K40---J40,"0")&" d)"),IF(J40="","🔴 Sin Fecha Compromiso",IF(TODAY()<=--J40,"🟢 En Plazo ("&TEXT(--J40-TODAY(),"0")&" d rest.)","🔴 Atrasado ("&TEXT(TODAY()---J40,"0")&" d)")))) | M40: =IF(G40="","", IF(ISNUMBER(SEARCH("DISPONIBLE", G40)), "🟢 DISPONIBLE INMEDIATO", IF(ISNUMBER(SEARCH("MANDANTE", G40)), IF(H40<>"","🔵 EN OPERACIÓN: " & H40,"🔵 EN OPERACIÓN"), IF(ISNUMBER(SEARCH("NO OPERATIVO", G40)), "🔴 NO OPERATIVO CRÍTICO", IF(K40<>"", "🟢 SALIÓ DE TALLER (DISPONIBLE)", IF(J40="", "🔴 EN TALLER (Falta Fecha Jefe Taller)", IF(TODAY()>J40, "🔴 DEMORA / RETRASO EN TALLER", IF(J40-TODAY()<=2, "🟡 YA POR SALIR DEL TALLER", "🟡 EN MANTENCIÓN SEGÚN PROGRAMA")))))))) -> 🔵 EN OPERACIÓN: FG COVER (Fenix Gold)
A41: 37 | B41: CT-367 | C41: VZPF-38 | D41: CAMION TOLVA | E41: SCANIA | F41: FG COVER | G41: 🔵 EN USO POR MANDANTE | H41: FG COVER (Fenix Gold) | L41: =IF(I41="","",IF(K41<>"",IF(--K41<=--J41,"🟢 Cumplido a Tiempo","🟡 Entregado con Atraso ("&TEXT(--K41---J41,"0")&" d)"),IF(J41="","🔴 Sin Fecha Compromiso",IF(TODAY()<=--J41,"🟢 En Plazo ("&TEXT(--J41-TODAY(),"0")&" d rest.)","🔴 Atrasado ("&TEXT(TODAY()---J41,"0")&" d)")))) | M41: =IF(G41="","", IF(ISNUMBER(SEARCH("DISPONIBLE", G41)), "🟢 DISPONIBLE INMEDIATO", IF(ISNUMBER(SEARCH("MANDANTE", G41)), IF(H41<>"","🔵 EN OPERACIÓN: " & H41,"🔵 EN OPERACIÓN"), IF(ISNUMBER(SEARCH("NO OPERATIVO", G41)), "🔴 NO OPERATIVO CRÍTICO", IF(K41<>"", "🟢 SALIÓ DE TALLER (DISPONIBLE)", IF(J41="", "🔴 EN TALLER (Falta Fecha Jefe Taller)", IF(TODAY()>J41, "🔴 DEMORA / RETRASO EN TALLER", IF(J41-TODAY()<=2, "🟡 YA POR SALIR DEL TALLER", "🟡 EN MANTENCIÓN SEGÚN PROGRAMA")))))))) -> 🔵 EN OPERACIÓN: FG COVER (Fenix Gold)
...

Sheet Parámetros
A1: GRUPO TERRACOP - PARÁMETROS Y LISTAS MAESTRAS
A2: Aquí puedes agregar nuevos mandantes, faenas o líneas de negocio. Se vincularán automáticamente con las demás hojas.
A4: Mandantes y Faenas Mineras | C4: Líneas de Negocio | E4: Estado de Cotización (Check 1) | G4: Resultado Adjudicación (Check 2) | I4: Estados de Flota (Check)
A5: FG COVER (Fenix Gold) | C5: Movimiento de Tierra | E5: 🟡 En Revisión / Preparación | G5: ⏳ En Evaluación por Mandante | I5: 🟢 DISPONIBLE INMEDIATO
A6: FG OOCC (Fenix Gold) | C6: Transporte | E6: 🔵 Cotización Enviada | G6: 🟢 Adjudicada / Ganada | I6: 🔵 EN USO POR MANDANTE
A7: Gold Fields - Salares Norte | C7: Obras Civiles | E7: 🔴 No Enviada / No Cotizar | G7: 🔴 No Adjudicada / Perdida | I7: 🟡 EN TALLER / MANTENCIÓN
A8: Minera Candelaria | C8: Maestranza Mirelva | G8: ⚪ Declinada / Desistida | I8: 🔴 NO OPERATIVO / FUERA SERVICIO
A9: Codelco División Salvador | C9: Servicios Integrales
A10: DOH MOP (Obras Públicas)
A11: Dirección de Vialidad MOP
A12: TRANSPORTE
A13: VIÑITA (Base Central)
A14: TALLER
A15: Otros Clientes Privados
